<?xml version="1.0"?>
<robot xmlns:xacro="http://www.ros.org/wiki/xacro" >

    <xacro:include filename="inertial_macros.xacro"/>

    <material name="white">
        <color rgba="1 1 1 1"/>
    </material>

    <material name="orange">
        <color rgba="1 0.3 0.1 1"/>
    </material>

    <material name="blue">
        <color rgba="0.2 0.2 1 1"/>
    </material>

    <material name="black">
        <color rgba="0 0 0 1"/>
    </material>

    <material name="red">
        <color rgba="1 0 0 1"/>
    </material>

    <link name="base_link">

    </link>

    <joint name="base_footprint_joint" type="fixed">
        <parent link="base_link"/>
        <child link="base_footprint"/>
        <origin xyz="0 0 0" rpy="0 0 0"/>
    </joint>

    <link name="base_footprint">
    </link>

    <joint name="chassis_joint" type="fixed">
        <parent link="base_link"/>
        <child link="chassis"/>
        <origin xyz="-0.1 0 0"/>
    </joint>

    <link name="chassis">
        <visual> 
            <origin xyz="0.411 0 0.311"/>
            <geometry>
                <box size ="0.822 0.8 0.622"/>
            </geometry>
            <material name="white"/>
        </visual>
        <collision> 
            <origin xyz="0.411 0 0.311"/>
            <geometry>
                <box size ="0.822 0.8 0.622"/>
            </geometry>
        </collision>
        <xacro:inertial_box mass="0.5" x="0.8" y="0.3" z="0.3">
            <origin xyz="-0.411 0 0.311" rpy="0 0 0"/>
        </xacro:inertial_box> 
    </link>

    <gazebo reference="chassis">
        <material>Gazebo/White</material>
    </gazebo>

    <!-- LEFT WHEEL LINK -->

    <joint name="left_wheel_joint" type="continuous">
        <parent link="base_link"/>
        <child link="left_wheel"/>
        <origin xyz="0 0.415 0" rpy="-${pi/2} 0 0"/>
        <axis xyz="0 0 1"/>
    </joint>

    <link name="left_wheel">
        <visual> 
            <geometry>
                <cylinder radius ="0.05" length="0.04"/>
            </geometry>
            <material name="blue"/>
        </visual>
        <collision> 
            <geometry>
                <cylinder radius ="0.05" length="0.04"/>
            </geometry>
        </collision>
        <xacro:inertial_cylinder mass="0.1" length="0.04" radius="0.05">
            <origin xyz="0 0 0" rpy="0 0 0"/>
        </xacro:inertial_cylinder>
    </link>

    <gazebo reference="left_wheel">
        <material>Gazebo/Blue</material>
    </gazebo>
    
    <joint name="right_wheel_joint" type="continuous">
        <parent link="base_link"/>
        <child link="right_wheel"/>
        <origin xyz="0 -0.415 0" rpy="${pi/2} 0 0"/>
        <axis xyz="0 0 -1"/>
    </joint>

    <link name="right_wheel">
        <visual> 
            <geometry>
                <cylinder radius ="0.05" length="0.04"/>
            </geometry>
            <material name="blue"/>
        </visual>
        <collision> 
            <geometry>
                <cylinder radius ="0.05" length="0.04"/>
            </geometry>
        </collision>
        <xacro:inertial_cylinder mass="0.1" length="0.04" radius="0.05">
            <origin xyz="0 0 0" rpy="0 0 0"/>
        </xacro:inertial_cylinder>
    </link>

    <gazebo reference="right_wheel">
        <material>Gazebo/Blue</material>
    </gazebo>
                                 
<!-- LEFT FRONT WHEEL LINK -->

    <joint name="left_front_wheel_joint" type="continuous">
        <parent link="base_link"/>
        <child link="left_front_wheel"/>
        <origin xyz="0.7 0.415 0" rpy="-${pi/2} 0 0"/>
        <axis xyz="0 0 1"/>
    </joint>

    <link name="left_front_wheel">
        <visual> 
            <geometry>
                <cylinder radius ="0.05" length="0.04"/>
        </geometry>
        <material name="blue"/>
    </visual>
    <collision> 
        <geometry>
            <cylinder radius ="0.05" length="0.04"/>
        </geometry>
    </collision>
    <xacro:inertial_cylinder mass="0.1" length="0.04" radius="0.05">
        <origin xyz="0 0 0" rpy="0 0 0"/>
    </xacro:inertial_cylinder>
</link>

    <gazebo reference="left_front_wheel">
        <material>Gazebo/Blue</material>
    </gazebo>

<!-- RIGHT FRONT WHEEL LINK -->

    <joint name="right_front_wheel_joint" type="continuous">
        <parent link="base_link"/>
        <child link="right_front_wheel"/>
        <origin xyz="0.7 -0.415 0" rpy="${pi/2} 0 0"/>
        <axis xyz="0 0 -1"/>
    </joint>

    <link name="right_front_wheel">
        <visual> 
            <geometry>
                <cylinder radius ="0.05" length="0.04"/>
            </geometry>
            <material name="blue"/>
    </visual>
    <collision> 
        <geometry>
            <cylinder radius ="0.05" length="0.04"/>
        </geometry>
    </collision>
    <xacro:inertial_cylinder mass="0.1" length="0.04" radius="0.05">
        <origin xyz="0 0 0" rpy="0 0 0"/>
    </xacro:inertial_cylinder>
</link>

    <gazebo reference="right_front_wheel">
        <material>Gazebo/Blue</material>
    </gazebo>

</robot>
